Workbook
Name RawQQC_: #REF!
Name RawQQC_: #REF!
Name RawQR_: #REF!
Name RawQR_: #REF!
Name RawQRC_: #REF!
Name RawQRC_: #REF!
Name U_RR: #REF!
Name U_RR: #REF!
Name Unit_RR: Report!$C$3
Name Unit_RR: #REF!

Sheet ForecastA(ctrlv)
Y17: Sales &COGS | AA17: Foreign Exchange I&E | AC17: Non-op. I&E | AE17: Events | BE17: (*) 첫 추정연도 분기배분
C18: ForecastA | D18: ForecastA | Y18: SG&A | AA18: Non-current assets | AC18: NI &Compre. Income | AE18: Dividend | BE18: ForecastQ
Y19: Other op. I&E | AA19: Current assets | AC19: Shareholders' Equity
X20: History | Y20: Interest I&E | AA20: Debt & Liabilities | AC20: Shares &Prices | AE20: Cash flow statement | BF20: Quarter | BJ20: Annual
B21: Period_CY_ | J21: 2000.12 | K21: 2001.12 | L21: 2002.12 | M21: 2003.12 | N21: 2004.12 | O21: 2005.12 | P21: 2006.12 | Q21: 2007.12 | R21: 2008.12 | S21: 2009.12 | T21: 2010.12 | U21: 2011.12 | V21: 2012.12 | W21: 2013.12 | X21: 2014.12 | Y21: 2015.12 | Z21: 2016.12 | AA21: 2017.12 | AB21: 2018.12 | AC21: 2019.12 | AD21: 2020.12 | AE21: 2021.12 | AF21: 2022.12 | AG21: 2023.12 | AH21: 2024.12 | AI21: 2025.12 | AJ21: 2026.12 | AK21: 2027.12 | AL21: 2028.12 | AM21: 2029.12 | AN21: 2030.12 | AO21: 2031.12 | AP21: 2032.12 | AQ21: 2033.12 | AR21: 2034.12 | AS21: 2035.12 | BD21: Period_CY_ | BF21: 2025.03 | BG21: 2025.06 | BH21: 2025.09 | BI21: 2025.12 | BJ21: 2025.12
B22: Period_FY_ | J22: 2000A | K22: 2001A | L22: 2002A | M22: 2003A | N22: 2004A | O22: 2005A | P22: 2006A | Q22: 2007A | R22: 2008A | S22: 2009A | T22: 2010A | U22: 2011A | V22: 2012A | W22: 2013A | X22: 2014A | Y22: 2015A | Z22: 2016A | AA22: 2017A | AB22: 2018A | AC22: 2019A | AD22: 2020A | AE22: 2021A | AF22: 2022A | AG22: 2023A | AH22: 2024A | AI22: 2025F | AJ22: 2026F | AK22: 2027F | AL22: 2028F | AM22: 2029F | AN22: 2030F | AO22: 2031F | AP22: 2032F | AQ22: 2033F | AR22: 2034F | AS22: 2035F | BD22: Period_FY_ | BF22: 2025_1F | BG22: 2025_2F | BH22: 2025_3F | BI22: 2025_4F | BJ22: 2025F
C24: Balance_BS : Asset - (Liability + Equity) | D24: BS: A-(L+E) | Z24: 0 | AA24: 0 | AB24: 0 | AC24: 0 | AD24: 0 | AE24: 0 | AF24: 0 | AG24: 0 | AH24: 0 | AI24: -6519.7335 | AJ24: -9417.1389 | AK24: -14913.418 | AL24: -24710.818 | AM24: -41483.768 | AN24: -69443.508 | AO24: -115223.96 | AP24: -189273.01 | AQ24: -308038.45 | AR24: -497402.88 | AS24: -798081.52 | AT24: FALSE | AX24: 필수입력
C25: Balance_CF : Cash(BS) - Cash(CF) | D25: CF: Cash(BS) - Cash(CF) | Z25: 0 | AA25: 0 | AB25: 0 | AC25: 0 | AD25: 0 | AE25: 0 | AF25: 0 | AG25: 0 | AH25: 0 | AI25: -6753.8315 | AJ25: -9885.3349 | AK25: -15615.712 | AL25: -25647.21 | AM25: -42654.258 | AN25: -70848.096 | AO25: -116862.65 | AP25: -191145.79 | AQ25: -310145.33 | AR25: -499743.86 | AS25: -800656.6 | AT25: FALSE | AX25: 선택입력
A28: Sales & COGS | BC28: Sales & COGS
B30: 200000 | C30: 매출액 | D30: Sales | E30: 1 | J30: 6392.2461 | K30: 6353.3612 | L30: 5478.9981 | M30: 5348.3267 | N30: 4854.0952 | O30: 4547.182 | P30: 5449.8714 | Q30: 6076.052 | R30: 8036.4935 | S30: 10390.595 | T30: 11217.013 | U30: 11920.167 | V30: 13324.821 | W30: 13852.042 | X30: 17276.48 | Y30: 19233.18 | Z30: 18825.015 | AA30: 16887.09 | AB30: 16730.894 | AC30: 17278.792 | AD30: 16970.859 | AE30: 18065.534 | AF30: 21239.082 | AG30: 29651.357 | AH30: 32670.268 | AI30: 35996.545 | AJ30: 39661.483 | AK30: 43699.56 | AL30: 48148.769 | AM30: 53050.968 | AN30: 58452.277 | AO30: 64403.513 | AP30: 70960.666 | AQ30: 78185.426 | AR30: 86145.765 | AS30: 94916.574 | BD30: 200000 | BE30: 매출액 | BF30: 8999.1363 | BG30: 8999.1363 | BH30: 8999.1363 | BI30: 8999.1363 | BJ30: 35996.545
C31: *컨센서스 | AI31: 30389.475 | AJ31: 30437.262 | AK31: 31298.569 | AL31: N/A | AM31: N/A | AN31: N/A | AO31: N/A | AP31: N/A | AQ31: N/A | AR31: N/A | AS31: N/A | BE31: (분기비중) | BF31: 0.25 | BG31: 0.25 | BH31: 0.25 | BI31: 0.25 | BJ31: 1
C32: (manual) | D32: (manual) | AI32: 32670.268 | AJ32: 35996.545 | AK32: 39661.483 | AL32: 43699.56 | AM32: 48148.769 | AN32: 53050.968 | AO32: 58452.277 | AP32: 64403.513 | AQ32: 70960.666 | AR32: 78185.426 | AS32: 86145.765
C33: (% growth) | D33: (% growth) | J33: 0 | K33: -0.0060831286 | L33: -0.13762214 | M33: -0.023849508 | N33: -0.092408614 | O33: -0.063227687 | P33: 0.19851623 | Q33: 0.11489823 | R33: 0.32265055 | S33: 0.29292642 | T33: 0.079535263 | U33: 0.062686339 | V33: 0.11783845 | W33: 0.039566835 | X33: 0.24721539 | Y33: 0.11325802 | Z33: -0.02122192 | AA33: -0.10294414 | AB33: -0.0092494326 | AC33: 0.032747682 | AD33: -0.017821443 | AE33: 0.064503217 | AF33: 0.17566865 | AG33: 0.39607526 | AH33: 0.10181359 | AI33: 0.10181359 | AJ33: 0.10181359 | AK33: 0.10181359 | AL33: 0.10181359 | AM33: 0.10181359 | AN33: 0.10181359 | AO33: 0.10181359 | AP33: 0.10181359 | AQ33: 0.10181359 | AR33: 0.10181359 | AS33: 0.10181359
B35: 200360 | C35: 매출원가 | D35: Cost of Sales | E35: 1 | J35: 5961.3531 | K35: 6282.5313 | L35: 5105.3947 | M35: 4847.7051 | N35: 4368.8944 | O35: 3933.0239 | P35: 4793.506 | Q35: 5420.8049 | R35: 7148.7166 | S35: 9441.7516 | T35: 9908.9062 | U35: 10751.856 | V35: 12075.949 | W35: 12732.365 | X35: 15864.906 | Y35: 17508.138 | Z35: 16895.275 | AA35: 15108.126 | AB35: 15069.747 | AC35: 15552.887 | AD35: 15573.996 | AE35: 16268.298 | AF35: 19726.334 | AG35: 27948.549 | AH35: 32887.201 | AI35: 36235.565 | AJ35: 39924.838 | AK35: 43989.729 | AL35: 48468.481 | AM35: 53403.231 | AN35: 58840.405 | AO35: 64831.158 | AP35: 71431.85 | AQ35: 78704.583 | AR35: 86717.779 | AS35: 95546.827 | BD35: 200360 | BE35: 매출원가 | BF35: 10788.268 | BG35: 10788.268 | BH35: 10788.268 | BI35: 3870.7595 | BJ35: 36235.565
C36: (manual) | D36: (manual) | AI36: 32887.201 | AJ36: 36235.565 | AK36: 39924.838 | AL36: 43989.729 | AM36: 48468.481 | AN36: 53403.231 | AO36: 58840.405 | AP36: 64831.158 | AQ36: 71431.85 | AR36: 78704.583 | AS36: 86717.779 | BE36: (분기비중) | BF36: 0.29772596 | BG36: 0.29772596 | BH36: 0.29772596 | BI36: 0.10682211 | BJ36: 1
C37: (% of sales) | D37: (% of sales) | J37: 0.93259131 | K37: 0.98885159 | L37: 0.93181173 | M37: 0.90639659 | N37: 0.90004299 | O37: 0.86493655 | P37: 0.87956314 | Q37: 0.89215907 | R37: 0.8895318 | S37: 0.90868249 | T37: 0.88338185 | U37: 0.90198871 | V37: 0.90627476 | W37: 0.91916881 | X37: 0.91829505 | Y37: 0.91030906 | Z37: 0.89749065 | AA37: 0.89465538 | AB37: 0.90071379 | AC37: 0.90011426 | AD37: 0.9176905 | AE37: 0.90051576 | AF37: 0.92877526 | AG37: 0.94257234 | AH37: 1.0066401 | AI37: 1.0066401 | AJ37: 1.0066401 | AK37: 1.0066401 | AL37: 1.0066401 | AM37: 1.0066401 | AN37: 1.0066401 | AO37: 1.0066401 | AP37: 1.0066401 | AQ37: 1.0066401 | AR37: 1.0066401 | AS37: 1.0066401 | BE37: (분기비중) | BF37: 0.29772596 | BG37: 0.29772596 | BH37: 0.29772596 | BI37: 0.10682211 | BJ37: 1
B39: 200810 | C39: 매출총이익 | D39: Gross Profit | J39: 430.89291 | K39: 70.82988 | L39: 373.60339 | M39: 500.62159 | N39: 485.20085 | O39: 614.15808 | P39: 656.3654 | Q39: 655.24712 | R39: 887.77696 | S39: 948.84324 | T39: 1308.1073 | U39: 1168.311 | V39: 1248.872 | W39: 1119.677 | X39: 1411.574 | Y39: 1725.042 | Z39: 1929.74 | AA39: 1778.964 | AB39: 1661.147 | AC39: 1725.905 | AD39: 1396.863 | AE39: 1797.236 | AF39: 1512.748 | AG39: 1702.808 | AH39: -216.933 | AI39: -239.01973 | AJ39: -263.35518 | AK39: -290.16832 | AL39: -319.7114 | AM39: -352.26236 | AN39: -388.12745 | AO39: -427.6441 | AP39: -471.18408 | AQ39: -519.15702 | AR39: -572.01426 | AS39: -630.25308 | BD39: 200810 | BE39: 매출총이익 | BF39: -1789.1322 | BG39: -1789.1322 | BH39: -1789.1322 | BI39: 5128.3768 | BJ39: -239.01973
C40: (% of sales) | D40: (% of sales) | J40: 0.067408686 | K40: 0.011148411 | L40: 0.068188268 | M40: 0.093603406 | N40: 0.099957011 | O40: 0.13506345 | P40: 0.12043686 | Q40: 0.10784093 | R40: 0.1104682 | S40: 0.09131751 | T40: 0.11661815 | U40: 0.098011295 | V40: 0.093725237 | W40: 0.080831187 | X40: 0.081704954 | Y40: 0.08969094 | Z40: 0.10250935 | AA40: 0.10534462 | AB40: 0.099286207 | AC40: 0.099885744 | AD40: 0.082309505 | AE40: 0.099484244 | AF40: 0.071224736 | AG40: 0.057427658 | AH40: -0.0066400741 | AI40: -0.0066400741 | AJ40: -0.0066400741 | AK40: -0.0066400741 | AL40: -0.0066400741 | AM40: -0.0066400741 | AN40: -0.0066400741 | AO40: -0.0066400741 | AP40: -0.0066400741 | AQ40: -0.0066400741 | AR40: -0.0066400741 | AS40: -0.0066400741 | BE40: (분기비중) | BF40: 7.4852908 | BG40: 7.4852908 | BH40: 7.4852908 | BI40: -21.455872 | BJ40: 1
A54: SG&A | BC54: SG&A
B56: 200820 | C56: 판매비와 관리비 등 | D56: SG&A | J56: 407.99263 | K56: 456.84213 | L56: 198.2763 | M56: 182.51919 | N56: 155.87193 | O56: 162.66844 | P56: 237.24228 | Q56: 256.95763 | R56: 320.87371 | S56: 367.80215 | T56: 552.8057 | U56: 432.715 | V56: 488.464 | W56: 415.58 | X56: 582.379 | Y56: 635.714 | Z56: 770.781 | AA56: 792.859 | AB56: 821.158 | AC56: 866.238 | AD56: 847.891 | AE56: 1043.732 | AF56: 937.846 | AG56: 917.378 | AH56: 1046.487 | AI56: 1152.4978 | AJ56: 1243.3807 | AK56: 1351.7707 | AL56: 1476.7942 | AM56: 1618.3513 | AN56: 1776.9137 | AO56: 1953.3935 | AP56: 2149.0603 | AQ56: 2365.4917 | AR56: 2604.5463 | AS56: 2868.3534 | BD56: 200820 | BE56: 판매비와 관리비 등 | BF56: 288.12446 | BG56: 288.12446 | BH56: 288.12446 | BI56: 288.12446 | BJ56: 1152.4978
C57: (% of sales) | J57: 0.063826177 | K57: 0.071905581 | L57: 0.036188423 | M57: 0.03412641 | N57: 0.032111429 | O57: 0.035773462 | P57: 0.043531721 | Q57: 0.042290229 | R57: 0.039927078 | S57: 0.035397603 | T57: 0.049282788 | U57: 0.036301085 | V57: 0.036658204 | W57: 0.030001353 | X57: 0.033709355 | Y57: 0.033052984 | Z57: 0.040944509 | AA57: 0.0469506 | AB57: 0.049080342 | AC57: 0.050133019 | AD57: 0.049961584 | AE57: 0.057774766 | AF57: 0.044156617 | AG57: 0.03093882 | AH57: 0.032031785 | AI57: 0.032016901 | AJ57: 0.031349829 | AK57: 0.030933279 | AL57: 0.030671484 | AM57: 0.030505594 | AN57: 0.030399392 | AO57: 0.030330542 | AP57: 0.030285233 | AQ57: 0.030254893 | AR57: 0.030234177 | AS57: 0.030219732 | BD57: 113091 | BE57: (분기비중) | BF57: 0.25 | BG57: 0.25 | BH57: 0.25 | BI57: 0.25 | BJ57: 1
B59: 200821 | C59: 인건비및복리후생비 | D59: Salaries and Wages | E59: 1 | J59: 94.429825 | K59: 89.858617 | L59: 83.296341 | M59: 84.624425 | N59: 81.517198 | O59: 85.682788 | P59: 111.95286 | Q59: 128.18888 | R59: 157.94683 | S59: 173.58203 | T59: 214.30022 | U59: 248.371 | V59: 265.646 | W59: 256.381 | X59: 310.644 | Y59: 330.179 | Z59: 419.216 | AA59: 431.846 | AB59: 475.484 | AC59: 466.614 | AD59: 498.26 | AE59: 513.969 | AF59: 538.377 | AG59: 583.153 | AH59: 633.54 | AI59: 698.04298 | AJ59: 769.11324 | AK59: 847.41942 | AL59: 933.69823 | AM59: 1028.7614 | AN59: 1133.5033 | AO59: 1248.9093 | AP59: 1376.0652 | AQ59: 1516.1674 | AR59: 1670.5338 | AS59: 1840.6169 | BD59: 200821 | BE59: 인건비및복리후생비 | BF59: 174.51074 | BG59: 174.51074 | BH59: 174.51074 | BI59: 174.51074 | BJ59: 698.04298
C60: (manual) | D60: (manual) | AI60: 633.54 | AJ60: 698.04298 | AK60: 769.11324 | AL60: 847.41942 | AM60: 933.69823 | AN60: 1028.7614 | AO60: 1133.5033 | AP60: 1248.9093 | AQ60: 1376.0652 | AR60: 1516.1674 | AS60: 1670.5338 | BE60: (분기비중) | BF60: 0.25 | BG60: 0.25 | BH60: 0.25 | BI60: 0.25 | BJ60: 1
C61: (% of sales) | D61: (% of sales) | J61: 0.014772558 | K61: 0.014143477 | L61: 0.015202842 | M61: 0.015822598 | N61: 0.01679349 | O61: 0.018843052 | P61: 0.020542294 | Q61: 0.021097397 | R61: 0.0196537 | S61: 0.016705688 | T61: 0.019104927 | U61: 0.020836201 | V61: 0.019936178 | W61: 0.018508535 | X61: 0.017980746 | Y61: 0.017167156 | Z61: 0.022269092 | AA61: 0.025572553 | AB61: 0.028419521 | AC61: 0.027005013 | AD61: 0.02935974 | AE61: 0.028450252 | AF61: 0.025348412 | AG61: 0.019666992 | AH61: 0.019391944 | AI61: 0.019391944 | AJ61: 0.019391944 | AK61: 0.019391944 | AL61: 0.019391944 | AM61: 0.019391944 | AN61: 0.019391944 | AO61: 0.019391944 | AP61: 0.019391944 | AQ61: 0.019391944 | AR61: 0.019391944 | AS61: 0.019391944 | BE61: (분기비중) | BF61: 0.25 | BG61: 0.25 | BH61: 0.25 | BI61: 0.25 | BJ61: 1
B63: 200822 | C63: 일반관리비 | D63: General & Administrative Expenses | E63: 1 | J63: 20.688801 | K63: 27.67948 | L63: 14.808061 | M63: 22.754691 | N63: 15.348698 | O63: 15.521722 | P63: 18.088112 | Q63: 21.839695 | R63: 26.715606 | S63: 31.753244 | T63: 41.608142 | U63: 35.147 | V63: 32.314 | W63: 41.462 | X63: 65.62 | Y63: 57.974 | Z63: 64.359 | AA63: 76.622 | AB63: 91.086 | AC63: 85.774 | AD63: 77.47 | AE63: 71.581 | AF63: 91.261 | AG63: 86.619 | AH63: 97.144 | AI63: 107.03458 | AJ63: 117.93215 | AK63: 129.93925 | AL63: 143.16883 | AM63: 157.74536 | AN63: 173.80598 | AO63: 191.50179 | AP63: 210.99928 | AQ63: 232.48187 | AR63: 256.15168 | AS63: 282.23141 | BD63: 200822 | BE63: 일반관리비 | BF63: 26.758645 | BG63: 26.758645 | BH63: 26.758645 | BI63: 26.758645 | BJ63: 107.03458
C64: (manual) | D64: (manual) | AI64: 97.144 | AJ64: 107.03458 | AK64: 117.93215 | AL64: 129.93925 | AM64: 143.16883 | AN64: 157.74536 | AO64: 173.80598 | AP64: 191.50179 | AQ64: 210.99928 | AR64: 232.48187 | AS64: 256.15168 | BE64: (분기비중) | BF64: 0.25 | BG64: 0.25 | BH64: 0.25 | BI64: 0.25 | BJ64: 1
C65: (% of sales) | D65: (% of sales) | J65: 0.0032365464 | K65: 0.0043566671 | L65: 0.0027026951 | M65: 0.004254544 | N65: 0.0031620101 | O65: 0.0034134816 | P65: 0.0033189979 | Q65: 0.0035943891 | R65: 0.0033242864 | S65: 0.0030559602 | T65: 0.0037093779 | U65: 0.0029485325 | V65: 0.0024250982 | W65: 0.0029932049 | X65: 0.0037982274 | Y65: 0.0030142701 | Z65: 0.0034188021 | AA65: 0.0045373122 | AB65: 0.0054441801 | AC65: 0.0049641202 | AD65: 0.0045648838 | AE65: 0.0039622964 | AF65: 0.004296843 | AG65: 0.0029212491 | AH65: 0.0029734681 | AI65: 0.0029734681 | AJ65: 0.0029734681 | AK65: 0.0029734681 | AL65: 0.0029734681 | AM65: 0.0029734681 | AN65: 0.0029734681 | AO65: 0.0029734681 | AP65: 0.0029734681 | AQ65: 0.0029734681 | AR65: 0.0029734681 | AS65: 0.0029734681 | BE65: (분기비중) | BF65: 0.25 | BG65: 0.25 | BH65: 0.25 | BI65: 0.25 | BJ65: 1
B67: 200823 | C67: 판매비 | D67: Sales Expenses | E67: 1 | J67: 191.86575 | K67: 267.7065 | L67: 31.221592 | M67: 31.909233 | N67: 18.81937 | O67: 17.567628 | P67: 23.197482 | Q67: 37.260634 | R67: 57.794431 | S67: 75.636948 | T67: 78.384366 | U67: 36.788 | V67: 95.866 | W67: 35.423 | X67: 84.189 | Y67: 89.96 | Z67: 121.97 | AA67: 119.899 | AB67: 132.945 | AC67: 128.449 | AD67: 61.645 | AE67: 227.182 | AF67: 90.93 | AG67: 66.057 | AH67: 100.249 | AI67: 110.45571 | AJ67: 121.7016 | AK67: 134.09248 | AL67: 147.74492 | AM67: 162.78735 | AN67: 179.36132 | AO67: 197.62274 | AP67: 217.74342 | AQ67: 239.91266 | AR67: 264.33902 | AS67: 291.25233 | BD67: 200823 | BE67: 판매비 | BF67: 27.613928 | BG67: 27.613928 | BH67: 27.613928 | BI67: 27.613928 | BJ67: 110.45571
C68: (manual) | D68: (manual) | AI68: 100.249 | AJ68: 110.45571 | AK68: 121.7016 | AL68: 134.09248 | AM68: 147.74492 | AN68: 162.78735 | AO68: 179.36132 | AP68: 197.62274 | AQ68: 217.74342 | AR68: 239.91266 | AS68: 264.33902 | BE68: (분기비중) | BF68: 0.25 | BG68: 0.25 | BH68: 0.25 | BI68: 0.25 | BJ68: 1
C69: (% of sales) | D69: (% of sales) | J69: 0.030015389 | K69: 0.0421362 | L69: 0.0056984127 | M69: 0.0059662087 | N69: 0.0038770088 | O69: 0.0038634099 | P69: 0.0042565191 | Q69: 0.0061323758 | R69: 0.0071914985 | S69: 0.0072793665 | T69: 0.0069879889 | U69: 0.0030861984 | V69: 0.0071945432 | W69: 0.0025572403 | X69: 0.0048730413 | Y69: 0.0046773336 | Z69: 0.0064791449 | AA69: 0.0071000391 | AB69: 0.0079460787 | AC69: 0.0074339109 | AD69: 0.0036324031 | AE69: 0.012575438 | AF69: 0.0042812585 | AG69: 0.0022277901 | AH69: 0.0030685087 | AI69: 0.0030685087 | AJ69: 0.0030685087 | AK69: 0.0030685087 | AL69: 0.0030685087 | AM69: 0.0030685087 | AN69: 0.0030685087 | AO69: 0.0030685087 | AP69: 0.0030685087 | AQ69: 0.0030685087 | AR69: 0.0030685087 | AS69: 0.0030685087 | BE69: (분기비중) | BF69: 0.25 | BG69: 0.25 | BH69: 0.25 | BI69: 0.25 | BJ69: 1
B71: 201130 | C71: 연구개발비 | D71: Research & Development | E71: 1 | J71: 47.914759 | K71: 41.874442 | L71: 49.963009 | M71: 29.863303 | N71: 30.367165 | O71: 34.660921 | P71: 54.787273 | Q71: 38.816925 | R71: 50.786809 | S71: 68.254526 | T71: 190.47143 | U71: 93.468 | V71: 73.874 | W71: 62.059 | X71: 60.383 | Y71: 63.472 | Z71: 87.62 | AA71: 85.934 | AB71: 109.949 | AC71: 151.432 | AD71: 177.527 | AE71: 190.025 | AF71: 178.612 | AG71: 138.787 | AH71: 154.923 | AI71: 170.69627 | AJ71: 188.07547 | AK71: 207.2241 | AL71: 228.32233 | AM71: 251.56865 | AN71: 277.18175 | AO71: 305.40262 | AP71: 336.49676 | AQ71: 370.7567 | AR71: 408.50477 | AS71: 450.09611 | BD71: 201130 | BE71: 연구개발비 | BF71: 42.674067 | BG71: 42.674067 | BH71: 42.674067 | BI71: 42.674067 | BJ71: 170.69627
C72: (manual) | D72: (manual) | AI72: 154.923 | AJ72: 170.69627 | AK72: 188.07547 | AL72: 207.2241 | AM72: 228.32233 | AN72: 251.56865 | AO72: 277.18175 | AP72: 305.40262 | AQ72: 336.49676 | AR72: 370.7567 | AS72: 408.50477 | BE72: (분기비중) | BF72: 0.25 | BG72: 0.25 | BH72: 0.25 | BI72: 0.25 | BJ72: 1
C73: (% of sales) | D73: (% of sales) | J73: 0.0074957626 | K73: 0.0065909116 | L73: 0.0091190047 | M73: 0.0055836722 | N73: 0.0062559887 | O73: 0.0076225058 | P73: 0.010052948 | Q73: 0.006388511 | R73: 0.0063195234 | S73: 0.0065688757 | T73: 0.016980583 | U73: 0.0078411653 | V73: 0.0055440895 | W73: 0.0044801337 | X73: 0.0034950985 | Y73: 0.0033001303 | Z73: 0.0046544452 | AA73: 0.0050887394 | AB73: 0.0065716154 | AC73: 0.0087640386 | AD73: 0.010460696 | AE73: 0.010518648 | AF73: 0.0084095913 | AG73: 0.004680629 | AH73: 0.004742018 | AI73: 0.004742018 | AJ73: 0.004742018 | AK73: 0.004742018 | AL73: 0.004742018 | AM73: 0.004742018 | AN73: 0.004742018 | AO73: 0.004742018 | AP73: 0.004742018 | AQ73: 0.004742018 | AR73: 0.004742018 | AS73: 0.004742018 | BE73: (분기비중) | BF73: 0.25 | BG73: 0.25 | BH73: 0.25 | BI73: 0.25 | BJ73: 1
B75: 201160 | C75: 광고선전비 | D75: Advertising Expenses | E75: 1 | J75: 15.734294 | K75: 3.83863 | L75: 2.369024 | M75: 2.963381 | N75: 3.713335 | O75: 4.749634 | P75: 24.90458 | Q75: 25.972288 | R75: 22.429208 | S75: 13.709182 | T75: 14.352038 | U75: 11.4 | V75: 11.506 | W75: 10.024 | X75: 13.801 | Y75: 14.455 | Z75: 14.813 | AA75: 10.592 | AB75: 0 | AC75: 0 | AD75: 0 | AE75: 0 | AF75: 0 | AG75: 0 | AH75: 0 | AI75: 0 | AJ75: 0 | AK75: 0 | AL75: 0 | AM75: 0 | AN75: 0 | AO75: 0 | AP75: 0 | AQ75: 0 | AR75: 0 | AS75: 0 | BD75: 201160 | BE75: 광고선전비 | BF75: 0 | BG75: 0 | BH75: 0 | BI75: 0 | BJ75: 0
C76: (manual) | D76: (manual) | AI76: 0 | AJ76: 0 | AK76: 0 | AL76: 0 | AM76: 0 | AN76: 0 | AO76: 0 | AP76: 0 | AQ76: 0 | AR76: 0 | AS76: 0 | BE76: (분기비중)
C77: (% of sales) | D77: (% of sales) | J77: 0.0024614656 | K77: 0.00060418885 | L77: 0.0004323827 | M77: 0.00055407629 | N77: 0.00076499015 | O77: 0.0010445225 | P77: 0.0045697555 | Q77: 0.0042745335 | R77: 0.0027909197 | S77: 0.0013193838 | T77: 0.0012794883 | U77: 0.00095636244 | V77: 0.00086350128 | W77: 0.00072364782 | X77: 0.00079883171 | Y77: 0.00075156578 | Z77: 0.00078687852 | AA77: 0.0006272247 | AB77: 0 | AC77: 0 | AD77: 0 | AE77: 0 | AF77: 0 | AG77: 0 | AH77: 0 | AI77: 0 | AJ77: 0 | AK77: 0 | AL77: 0 | AM77: 0 | AN77: 0 | AO77: 0 | AP77: 0 | AQ77: 0 | AR77: 0 | AS77: 0 | BE77: (분기비중)
B79: 201080 | C79: 유형자산 감가상각비 | D79: Depreciation (SG&A) | J79: 37.3483 | K79: 25.873568 | L79: 16.607373 | M79: 10.400645 | N79: 6.054871 | O79: 4.316226 | P79: 3.816779 | Q79: 4.544511 | R79: 4.847228 | S79: 4.468217 | T79: 6.656417 | U79: 7.093 | V79: 8.302 | W79: 8.818 | X79: 9.091 | Y79: 10.094 | Z79: 11.269 | AA79: 11.852 | AB79: 11.694 | AC79: 17.807 | AD79: 27.58 | AE79: 34.378 | AF79: 34.859 | AG79: 37.749 | AH79: 53.999 | AI79: 58.062225 | AJ79: 39.129134 | AK79: 26.369798 | AL79: 17.771061 | AM79: 11.976225 | AN79: 8.0709842 | AO79: 5.4391753 | AP79: 3.665554 | AQ79: 2.47028 | AR79: 1.6647643 | AS79: 1.1219133 | BD79: 201080 | BE79: 유형자산 감가상각비 | BF79: 14.515556 | BG79: 14.515556 | BH79: 14.515556 | BI79: 14.515556 | BJ79: 58.062225
B80: 201090+201100 | C80: 무형자산상각비 | D80: Amortization (SG&A) | J80: 0.010894 | K80: 0.010894 | L80: 0.010894 | M80: 0.003511 | N80: 0.051299 | O80: 0.169521 | P80: 0.495198 | Q80: 0.334702 | R80: 0.353596 | S80: 0.398002 | T80: 7.033087 | U80: 0.448 | V80: 0.956 | W80: 1.413 | X80: 38.651 | Y80: 69.58 | Z80: 51.534 | AA80: 56.114 | AB80: 0 | AC80: 16.162 | AD80: 5.409 | AE80: 6.597 | AF80: 3.807 | AG80: 5.013 | AH80: 6.632 | AI80: 8.2060772 | AJ80: 7.4290818 | AK80: 6.7256564 | AL80: 6.0888352 | AM80: 5.5123116 | AN80: 4.9903764 | AO80: 4.5178608 | AP80: 4.0900855 | AQ80: 3.7028142 | AR80: 3.3522119 | AS80: 3.0348065 | BD80: 201090+201100 | BE80: 무형자산상각비 | BF80: 2.0515193 | BG80: 2.0515193 | BH80: 2.0515193 | BI80: 2.0515193 | BJ80: 8.2060772
A91: Operating Income | BC91: Other Operating Income & Expenses
B93: 203590 | C93: 기타영업수익 | D93: Other Operating Income | J93: 0 | K93: 0 | L93: 0 | M93: 0 | N93: 0 | O93: 0 | P93: 0 | Q93: 0 | R93: 0 | S93: 0 | T93: 0 | U93: 202.47927 | V93: 0 | W93: 0 | X93: 0 | Y93: 0 | Z93: 0 | AA93: 0 | AB93: 0 | AC93: 0 | AD93: 0 | AE93: 0 | AF93: 0 | AG93: 0 | AH93: 0 | AI93: 0 | AJ93: 0 | AK93: 0 | AL93: 0 | AM93: 0 | AN93: 0 | AO93: 0 | AP93: 0 | AQ93: 0 | AR93: 0 | AS93: 0 | BD93: 203590 | BE93: 기타영업수익 | BF93: 0 | BG93: 0 | BH93: 0 | BI93: 0 | BJ93: 0
...

Sheet Annual(ctrlv)
C14: Annual | D14: BaseA
B17: Period_CY_ | J17: 2014.12 | K17: 2015.12 | L17: 2016.12 | M17: 2017.12 | N17: 2018.12 | O17: 2019.12 | P17: 2020.12 | Q17: 2021.12 | R17: 2022.12 | S17: 2023.12 | T17: 2024.12 | U17: 2025.12 | V17: 2026.12 | W17: 2027.12 | X17: 2028.12 | Y17: 2029.12
B18: Period_FY_ | J18: 2014A | K18: 2015A | L18: 2016A | M18: 2017A | N18: 2018A | O18: 2019A | P18: 2020A | Q18: 2021A | R18: 2022A | S18: 2023A | T18: 2024A | U18: 2025F | V18: 2026F | W18: 2027F | X18: 2028F | Y18: 2029F
A25: Income Statement
B27: 200000 | C27: 매출액 | D27: Sales | J27: 17276.48 | K27: 19233.18 | L27: 18825.015 | M27: 16887.09 | N27: 16730.894 | O27: 17278.792 | P27: 16970.859 | Q27: 18065.534 | R27: 21239.082 | S27: 29651.357 | T27: 32670.268 | U27: 35996.545 | V27: 39661.483 | W27: 43699.56 | X27: 48148.769 | Y27: 53050.968
B29: 200001 | C29: 순매출액 (직접 입력) | D29: Net sales (manual)
B31: 200360 | C31: 매출원가 | D31: Cost of Sales | J31: 15864.906 | K31: 17508.138 | L31: 16895.275 | M31: 15108.126 | N31: 15069.747 | O31: 15552.887 | P31: 15573.996 | Q31: 16268.298 | R31: 19726.334 | S31: 27948.549 | T31: 32887.201 | U31: 36235.565 | V31: 39924.838 | W31: 43989.729 | X31: 48468.481 | Y31: 53403.231
B33: 200810 | C33: 매출총이익 | D33: Gross Profit | J33: 1411.574 | K33: 1725.042 | L33: 1929.74 | M33: 1778.964 | N33: 1661.147 | O33: 1725.905 | P33: 1396.863 | Q33: 1797.236 | R33: 1512.748 | S33: 1702.808 | T33: -216.933 | U33: -239.01973 | V33: -263.35518 | W33: -290.16832 | X33: -319.7114 | Y33: -352.26236
B35: 200820 | C35: 판매비와 관리비 | D35: SG&A | J35: 582.379 | K35: 635.714 | L35: 770.781 | M35: 792.859 | N35: 821.158 | O35: 866.238 | P35: 847.891 | Q35: 1043.732 | R35: 937.846 | S35: 917.378 | T35: 1046.487 | U35: 1152.4978 | V35: 1243.3807 | W35: 1351.7707 | X35: 1476.7942 | Y35: 1618.3513
B36: 200821 | C36: 인건비및복리후생비 | D36: Salaries and Wages | J36: 310.644 | K36: 330.179 | L36: 419.216 | M36: 431.846 | N36: 475.484 | O36: 466.614 | P36: 498.26 | Q36: 513.969 | R36: 538.377 | S36: 583.153 | T36: 633.54 | U36: 698.04298 | V36: 769.11324 | W36: 847.41942 | X36: 933.69823 | Y36: 1028.7614
B37: 200822 | C37: 일반관리비 | D37: General & Administrative Expenses | J37: 65.62 | K37: 57.974 | L37: 64.359 | M37: 76.622 | N37: 91.086 | O37: 85.774 | P37: 77.47 | Q37: 71.581 | R37: 91.261 | S37: 86.619 | T37: 97.144 | U37: 107.03458 | V37: 117.93215 | W37: 129.93925 | X37: 143.16883 | Y37: 157.74536
B38: 200823 | C38: 판매비 | D38: Sales Expenses | J38: 84.189 | K38: 89.96 | L38: 121.97 | M38: 119.899 | N38: 132.945 | O38: 128.449 | P38: 61.645 | Q38: 227.182 | R38: 90.93 | S38: 66.057 | T38: 100.249 | U38: 110.45571 | V38: 121.7016 | W38: 134.09248 | X38: 147.74492 | Y38: 162.78735
B39: 201130 | C39: 연구개발비 | D39: Research & Development | J39: 60.383 | K39: 63.472 | L39: 87.62 | M39: 85.934 | N39: 109.949 | O39: 151.432 | P39: 177.527 | Q39: 190.025 | R39: 178.612 | S39: 138.787 | T39: 154.923 | U39: 170.69627 | V39: 188.07547 | W39: 207.2241 | X39: 228.32233 | Y39: 251.56865
B40: 201160 | C40: 광고선전비 | D40: Advertising Expenses | J40: 13.801 | K40: 14.455 | L40: 14.813 | M40: 10.592 | N40: 0 | O40: 0 | P40: 0 | Q40: 0 | R40: 0 | S40: 0 | T40: 0 | U40: 0 | V40: 0 | W40: 0 | X40: 0 | Y40: 0
B41: 201080 | C41: 유형자산 감가상각비 | D41: Depreciation (SG&A) | J41: 9.091 | K41: 10.094 | L41: 11.269 | M41: 11.852 | N41: 11.694 | O41: 17.807 | P41: 27.58 | Q41: 34.378 | R41: 34.859 | S41: 37.749 | T41: 53.999 | U41: 58.062225 | V41: 39.129134 | W41: 26.369798 | X41: 17.771061 | Y41: 11.976225
B42: 201090+201100 | C42: 무형자산상각비 | D42: Amortization (SG&A) | J42: 38.651 | K42: 69.58 | L42: 51.534 | M42: 56.114 | N42: 0 | O42: 16.162 | P42: 5.409 | Q42: 6.597 | R42: 3.807 | S42: 5.013 | T42: 6.632 | U42: 8.2060772 | V42: 7.4290818 | W42: 6.7256564 | X42: 6.0888352 | Y42: 5.5123116
B44: 203590 | C44: 기타영업수익 | D44: Other Operating Income | J44: 0 | K44: 0 | L44: 0 | M44: 0 | N44: 0 | O44: 0 | P44: 0 | Q44: 0 | R44: 0 | S44: 0 | T44: 0 | U44: 0 | V44: 0 | W44: 0 | X44: 0 | Y44: 0
B45: 203600 | C45: 이자수익 | D45: Interest Income | J45: 0 | K45: 0 | L45: 0 | M45: 0 | N45: 0 | O45: 0 | P45: 0 | Q45: 0 | R45: 0 | S45: 0 | T45: 0 | U45: 0 | V45: 0 | W45: 0 | X45: 0 | Y45: 0
B46: 203610 | C46: 배당금수익 | D46: Dividend Income | J46: 0 | K46: 0 | L46: 0 | M46: 0 | N46: 0 | O46: 0 | P46: 0 | Q46: 0 | R46: 0 | S46: 0 | T46: 0 | U46: 0 | V46: 0 | W46: 0 | X46: 0 | Y46: 0
B47: 203620 | C47: 외환거래이익 | D47: Gains on Foreign Exchange | J47: 0 | K47: 0 | L47: 0 | M47: 0 | N47: 0 | O47: 0 | P47: 0 | Q47: 0 | R47: 0 | S47: 0 | T47: 0 | U47: 0 | V47: 0 | W47: 0 | X47: 0 | Y47: 0
B48: 203800 | C48: 투자자산평가이익 | D48: Gains on Investment Assets | J48: 0 | K48: 0 | L48: 0 | M48: 0 | N48: 0 | O48: 0 | P48: 0 | Q48: 0 | R48: 0 | S48: 0 | T48: 0 | U48: 0 | V48: 0 | W48: 0 | X48: 0 | Y48: 0
B49: 203591 | C49: 기타 기타수익 | D49: Others | J49: 0 | K49: 0 | L49: 0 | M49: 0 | N49: 0 | O49: 0 | P49: 0 | Q49: 0 | R49: 0 | S49: 0 | T49: 0 | U49: 0 | V49: 0 | W49: 0 | X49: 0 | Y49: 0
B51: 204030 | C51: 기타영업비용 | D51: Other Operating Expenses | J51: 0 | K51: 0 | L51: 0 | M51: 0 | N51: 0 | O51: 0 | P51: 0 | Q51: 0 | R51: 0 | S51: 0 | T51: 0 | U51: 0 | V51: 0 | W51: 0 | X51: 0 | Y51: 0
B52: 204040 | C52: 이자비용 | D52: Interest Expenses | J52: 0 | K52: 0 | L52: 0 | M52: 0 | N52: 0 | O52: 0 | P52: 0 | Q52: 0 | R52: 0 | S52: 0 | T52: 0 | U52: 0 | V52: 0 | W52: 0 | X52: 0 | Y52: 0
B53: 204050 | C53: 외환거래손실 | D53: Losses on Foreign Exchange | J53: 0 | K53: 0 | L53: 0 | M53: 0 | N53: 0 | O53: 0 | P53: 0 | Q53: 0 | R53: 0 | S53: 0 | T53: 0 | U53: 0 | V53: 0 | W53: 0 | X53: 0 | Y53: 0
B54: 204240 | C54: 투자자산평가손실 | D54: Losses on Investment Assets | J54: 0 | K54: 0 | L54: 0 | M54: 0 | N54: 0 | O54: 0 | P54: 0 | Q54: 0 | R54: 0 | S54: 0 | T54: 0 | U54: 0 | V54: 0 | W54: 0 | X54: 0 | Y54: 0
B55: 204031 | C55: 기타 기타비용 | D55: Others | J55: 0 | K55: 0 | L55: 0 | M55: 0 | N55: 0 | O55: 0 | P55: 0 | Q55: 0 | R55: 0 | S55: 0 | T55: 0 | U55: 0 | V55: 0 | W55: 0 | X55: 0 | Y55: 0
B57: 201370 | C57: 영업이익 | D57: Operating Income | J57: 829.195 | K57: 1089.328 | L57: 1158.959 | M57: 986.105 | N57: 839.989 | O57: 859.667 | P57: 548.972 | Q57: 753.504 | R57: 574.902 | S57: 785.43 | T57: -1263.42 | U57: -1391.5176 | V57: -1506.7359 | W57: -1641.939 | X57: -1796.5056 | Y57: -1970.6137
... B108: 203300 | C108: 총포괄이익 | D108: Total Comprehensive Income | J108: 453.414 | K108: 701.215 | L108: 842.416 | M108: 444.145 | N108: 328.166 | O108: 540.166 | P108: 137.01 | Q108: 710.987 | R108: 615.028 | S108: 626.027 | T108: -689.8 | U108: -1041.3797 | V108: -1134.9453 | W108: -1242.9889 | X108: -1365.3063 | Y108: -1502.2412
A117: Balance Sheet
B119: 110000 | C119: 자산총계 | D119: Assets | J119: 18244.6 | K119: 19350.103 | L119: 19873.443 | M119: 18431.902 | N119: 18054.609 | O119: 18226.972 | P119: 17939.274 | Q119: 19637.264 | R119: 20911.708 | S119: 23714.495 | T119: 27005.385 | U119: 23159.065 | V119: 24809.063 | W119: 26823.987 | X119: 29220.405 | Y119: 32030.162
B121: 110010 | C121: 비유동자산 | D121: Non-Current Assets | J121: 4803.452 | K121: 5121.679 | L121: 4935.519 | M121: 5182.062 | N121: 4717.841 | O121: 5054.979 | P121: 4540.331 | Q121: 5110.86 | R121: 5394.964 | S121: 5101.065 | T121: 5904.722 | U121: 5561.0318 | V121: 5292.6432 | W121: 5075.2756 | X121: 4892.5399 | Y121: 4733.3679
B122: 110020 | C122: 유형자산 | D122: Tangible Assets | J122: 1710.644 | K122: 1754.185 | L122: 1498.089 | M122: 1398.791 | N122: 1436.574 | O122: 1419.749 | P122: 967.47 | Q122: 1012.128 | R122: 1048.81 | S122: 1204.52 | T122: 1289.154 | U122: 1061.8577 | V122: 908.67878 | W122: 805.44887 | X122: 735.88046 | Y122: 688.99711
B123: 190010 | C123: 토지 | D123: Land | J123: 587.831 | K123: 590.645 | L123: 320.006 | M123: 330.733 | N123: 333.706 | O123: 349.836 | P123: 365.665 | Q123: 397.099 | R123: 363 | S123: 363.045 | T123: 368.27 | U123: 368.27 | V123: 368.27 | W123: 368.27 | X123: 368.27 | Y123: 368.27
B124: 190020 | C124: 설비자산 | D124: Plant Assets | J124: 1035.144 | K124: 1049.46 | L124: 1118.283 | M124: 986.336 | N124: 899.627 | O124: 981.35 | P124: 521.927 | Q124: 505.132 | R124: 487.634 | S124: 628.474 | T124: 677.768 | U124: 456.75954 | V124: 307.81812 | W124: 207.44394 | X124: 139.80005 | Y124: 94.21366
B125: 190150 | C125: 건설중인자산 | D125: Construction in Progress | J125: 65.953 | K125: 94.092 | L125: 41.176 | M125: 65.922 | N125: 187.959 | O125: 73.872 | P125: 64.061 | Q125: 92.182 | R125: 178.217 | S125: 193.204 | T125: 223.833 | U125: 223.833 | V125: 223.833 | W125: 223.833 | X125: 223.833 | Y125: 223.833
B126: 190160 | C126: 기타유형자산 | D126: Other Property Plant Equipment | J126: 21.716 | K126: 19.988 | L126: 18.624 | M126: 15.8 | N126: 15.282 | O126: 14.691 | P126: 15.817 | Q126: 17.715 | R126: 19.959 | S126: 19.797 | T126: 19.283 | U126: 12.995146 | V126: 8.7576529 | W126: 5.9019332 | X126: 3.9774145 | Y126: 2.6804482
B127: 110610 | C127: 무형자산 | D127: Intangible Assets | J127: 874.253 | K127: 857.312 | L127: 810.336 | M127: 760.228 | N127: 711.198 | O127: 697.843 | P127: 703.436 | Q127: 718.28 | R127: 720.626 | S127: 724.427 | T127: 750.741 | U127: 738.23515 | V127: 726.91341 | W127: 716.66368 | X127: 707.38445 | Y127: 698.98383
B128: 190170 | C128: 영업권 | D128: Goodwill | J128: 593.621 | K128: 618.594 | L128: 618.594 | M128: 618.594 | N128: 618.594 | O128: 618.594 | P128: 617.684 | Q128: 617.684 | R128: 617.684 | S128: 617.684 | T128: 618.663 | U128: 618.663 | V128: 618.663 | W128: 618.663 | X128: 618.663 | Y128: 618.663
B129: 110611 | C129: 기타무형자산 | D129: Other Intangible Assets | J129: 280.632 | K129: 238.718 | L129: 191.742 | M129: 141.634 | N129: 92.604 | O129: 79.249 | P129: 85.752 | Q129: 100.596 | R129: 102.942 | S129: 106.743 | T129: 132.078 | U129: 119.57215 | V129: 108.25041 | W129: 98.000684 | X129: 88.721453 | Y129: 80.32083
...

Sheet Quarter
C2: Quarter | D2: BaseQ
B5: Period_CY_ | J5: 2022.03 | K5: 2022.06 | L5: 2022.09 | M5: 2022.12 | N5: 2023.03 | O5: 2023.06 | P5: 2023.09 | Q5: 2023.12 | R5: 2024.03 | S5: 2024.06 | T5: 2024.09 | U5: 2024.12 | V5: 2025.03 | W5: 2025.06 | X5: 2025.09 | Y5: 2025.12 | Z5: 2026.03 | AA5: 2026.06 | AB5: 2026.09 | AC5: 2026.12 | AD5: 2027.03 | AE5: 2027.06 | AF5: 2027.09 | AG5: 2027.12
B6: Period_FY_ | J6: 2022_1A | K6: 2022_2A | L6: 2022_3A | M6: 2022_4A | N6: 2023_1A | O6: 2023_2A | P6: 2023_3A | Q6: 2023_4A | R6: 2024_1A | S6: 2024_2A | T6: 2024_3A | U6: 2024_4A | V6: 2025_1F | W6: 2025_2F | X6: 2025_3F | Y6: 2025_4F | Z6: 2026_1F | AA6: 2026_2F | AB6: 2026_3F | AC6: 2026_4F | AD6: 2027_1F | AE6: 2027_2F | AF6: 2027_3F | AG6: 2027_4F
A13: Income Statement
B15: 200000 | C15: 매출액 | D15: Sales | J15: 4145.303 | K15: 5579.448 | L15: 5430.844 | M15: 6083.487 | N15: 6031.081 | O15: 7163.359 | P15: 7858.53 | Q15: 8598.387 | R15: 8545.258 | S15: 8621.236 | T15: 8256.906 | U15: 7246.868 | V15: 8999.1363 | W15: 8999.1363 | X15: 8999.1363 | Y15: 8999.1363 | Z15: 9915.3706 | AA15: 9915.3706 | AB15: 9915.3706 | AC15: 9915.3706 | AD15: 10924.89 | AE15: 10924.89 | AF15: 10924.89 | AG15: 10924.89
B17: 200001 | C17: 순매출액 (직접 입력) | D17: Net sales (manual)
B19: 200360 | C19: 매출원가 | D19: Cost of Sales | J19: 3774.063 | K19: 5137.759 | L19: 5097.562 | M19: 5716.95 | N19: 5651.16 | O19: 6765.776 | P19: 7342.408 | Q19: 8189.205 | R19: 8011.925 | S19: 8279.049 | T19: 7908.598 | U19: 8687.629 | V19: 10788.268 | W19: 10788.268 | X19: 10788.268 | Y19: 3870.7595 | Z19: 4264.8554 | AA19: 4264.8554 | AB19: 4264.8554 | AC19: 27130.271 | AD19: 29892.502 | AE19: 29892.502 | AF19: 29892.502 | AG19: -45687.776
B21: 200810 | C21: 매출총이익 | D21: Gross Profit | J21: 371.24 | K21: 441.689 | L21: 333.282 | M21: 366.537 | N21: 379.921 | O21: 397.583 | P21: 516.122 | Q21: 409.182 | R21: 533.333 | S21: 342.187 | T21: 348.308 | U21: -1440.761 | V21: -1789.1322 | W21: -1789.1322 | X21: -1789.1322 | Y21: 5128.3768 | Z21: 5650.5152 | AA21: 5650.5152 | AB21: 5650.5152 | AC21: -17214.901 | AD21: -18967.612 | AE21: -18967.612 | AF21: -18967.612 | AG21: 56612.666
B23: 200820 | C23: 판매비와 관리비 | D23: SG&A | J23: 199.759 | K23: 266.281 | L23: 179.576 | M23: 292.23 | N23: 206.409 | O23: 174.032 | P23: 272.253 | Q23: 264.684 | R23: 282.42 | S23: 194.884 | T23: 234.017 | U23: 335.166 | V23: 288.12446 | W23: 288.12446 | X23: 288.12446 | Y23: 288.12446 | Z23: 310.84517 | AA23: 310.84517 | AB23: 310.84517 | AC23: 310.84517 | AD23: 337.94268 | AE23: 337.94268 | AF23: 337.94268 | AG23: 337.94268
B24: 200821 | C24: 인건비및복리후생비 | D24: Salaries and Wages | J24: 117.485 | K24: 162.113 | L24: 122.696 | M24: 136.083 | N24: 121.822 | O24: 167.215 | P24: 128.854 | Q24: 165.262 | R24: 204.274 | S24: 102.038 | T24: 136.546 | U24: 190.682 | V24: 174.51074 | W24: 174.51074 | X24: 174.51074 | Y24: 174.51074 | Z24: 192.27831 | AA24: 192.27831 | AB24: 192.27831 | AC24: 192.27831 | AD24: 211.85485 | AE24: 211.85485 | AF24: 211.85485 | AG24: 211.85485
B25: 200822 | C25: 일반관리비 | D25: General & Administrative Expenses | J25: 15.491 | K25: 24.796 | L25: 19.296 | M25: 31.678 | N25: 18.116 | O25: 24.288 | P25: 19.156 | Q25: 25.059 | R25: 18.857 | S25: 18.449 | T25: 21.023 | U25: 38.815 | V25: 26.758645 | W25: 26.758645 | X25: 26.758645 | Y25: 26.758645 | Z25: 29.483038 | AA25: 29.483038 | AB25: 29.483038 | AC25: 29.483038 | AD25: 32.484812 | AE25: 32.484812 | AF25: 32.484812 | AG25: 32.484812
B26: 200823 | C26: 판매비 | D26: Sales Expenses | J26: 14.247 | K26: 21.516 | L26: -13.871 | M26: 69.038 | N26: 10.834 | O26: -50.637 | P26: 84.155 | Q26: 21.705 | R26: 19.698 | S26: 20.4 | T26: 22.222 | U26: 37.929 | V26: 27.613928 | W26: 27.613928 | X26: 27.613928 | Y26: 27.613928 | Z26: 30.425401 | AA26: 30.425401 | AB26: 30.425401 | AC26: 30.425401 | AD26: 33.52312 | AE26: 33.52312 | AF26: 33.52312 | AG26: 33.52312
B27: 201130 | C27: 연구개발비 | D27: Research & Development | J27: 42.902 | K27: 48.475 | L27: 41.763 | M27: 45.472 | N27: 45.21 | O27: 22.375 | P27: 29.217 | Q27: 41.985 | R27: 27.414 | S27: 36.468 | T27: 38.865 | U27: 52.176 | V27: 42.674067 | W27: 42.674067 | X27: 42.674067 | Y27: 42.674067 | Z27: 47.018866 | AA27: 47.018866 | AB27: 47.018866 | AC27: 47.018866 | AD27: 51.806026 | AE27: 51.806026 | AF27: 51.806026 | AG27: 51.806026
B28: 201160 | C28: 광고선전비 | D28: Advertising Expenses | J28: 0 | K28: 0 | L28: 0 | M28: 0 | N28: 0 | O28: 0 | P28: 0 | Q28: 0 | R28: 0 | S28: 0 | T28: 0 | U28: 0 | V28: 0 | W28: 0 | X28: 0 | Y28: 0 | Z28: 0 | AA28: 0 | AB28: 0 | AC28: 0 | AD28: 0 | AE28: 0 | AF28: 0 | AG28: 0
B29: 201080 | C29: 유형자산 감가상각비 | D29: Depreciation (SG&A) | J29: 8.559 | K29: 8.49 | L29: 8.818 | M29: 8.992 | N29: 9.266 | O29: 9.543 | P29: 9.632 | Q29: 9.308 | R29: 10.654 | S29: 16.019 | T29: 13.608 | U29: 13.718 | V29: 14.515556 | W29: 14.515556 | X29: 14.515556 | Y29: 14.515556 | Z29: 9.7822836 | AA29: 9.7822836 | AB29: 9.7822836 | AC29: 9.7822836 | AD29: 6.5924495 | AE29: 6.5924495 | AF29: 6.5924495 | AG29: 6.5924495
B30: 201090+201100 | C30: 무형자산상각비 | D30: Amortization (SG&A) | J30: 1.075 | K30: 0.891 | L30: 0.874 | M30: 0.967 | N30: 1.161 | O30: 1.248 | P30: 1.239 | Q30: 1.365 | R30: 1.523 | S30: 1.51 | T30: 1.753 | U30: 1.846 | V30: 2.0515193 | W30: 2.0515193 | X30: 2.0515193 | Y30: 2.0515193 | Z30: 1.8572704 | AA30: 1.8572704 | AB30: 1.8572704 | AC30: 1.8572704 | AD30: 1.6814141 | AE30: 1.6814141 | AF30: 1.6814141 | AG30: 1.6814141
B32: 203590 | C32: 기타영업수익 | D32: Other Operating Income | J32: 0 | K32: 0 | L32: 0 | M32: 0 | N32: 0 | O32: 0 | P32: 0 | Q32: 0 | R32: 0 | S32: 0 | T32: 0 | U32: 0 | V32: 0 | W32: 0 | X32: 0 | Y32: 0 | Z32: 0 | AA32: 0 | AB32: 0 | AC32: 0 | AD32: 0 | AE32: 0 | AF32: 0 | AG32: 0
B33: 203600 | C33: 이자수익 | D33: Interest Income | J33: 0 | K33: 0 | L33: 0 | M33: 0 | N33: 0 | O33: 0 | P33: 0 | Q33: 0 | R33: 0 | S33: 0 | T33: 0 | U33: 0 | V33: 0 | W33: 0 | X33: 0 | Y33: 0 | Z33: 0 | AA33: 0 | AB33: 0 | AC33: 0 | AD33: 0 | AE33: 0 | AF33: 0 | AG33: 0
B34: 203610 | C34: 배당금수익 | D34: Dividend Income | J34: 0 | K34: 0 | L34: 0 | M34: 0 | N34: 0 | O34: 0 | P34: 0 | Q34: 0 | R34: 0 | S34: 0 | T34: 0 | U34: 0 | V34: 0 | W34: 0 | X34: 0 | Y34: 0 | Z34: 0 | AA34: 0 | AB34: 0 | AC34: 0 | AD34: 0 | AE34: 0 | AF34: 0 | AG34: 0
B35: 203620 | C35: 외환거래이익 | D35: Gains on Foreign Exchange | J35: 0 | K35: 0 | L35: 0 | M35: 0 | N35: 0 | O35: 0 | P35: 0 | Q35: 0 | R35: 0 | S35: 0 | T35: 0 | U35: 0 | V35: 0 | W35: 0 | X35: 0 | Y35: 0 | Z35: 0 | AA35: 0 | AB35: 0 | AC35: 0 | AD35: 0 | AE35: 0 | AF35: 0 | AG35: 0
B36: 203800 | C36: 투자자산평가이익 | D36: Gains on Investment Assets | J36: 0 | K36: 0 | L36: 0 | M36: 0 | N36: 0 | O36: 0 | P36: 0 | Q36: 0 | R36: 0 | S36: 0 | T36: 0 | U36: 0 | V36: 0 | W36: 0 | X36: 0 | Y36: 0 | Z36: 0 | AA36: 0 | AB36: 0 | AC36: 0 | AD36: 0 | AE36: 0 | AF36: 0 | AG36: 0
B37: 203591 | C37: 기타 기타수익 | D37: Others | J37: 0 | K37: 0 | L37: 0 | M37: 0 | N37: 0 | O37: 0 | P37: 0 | Q37: 0 | R37: 0 | S37: 0 | T37: 0 | U37: 0 | V37: 0 | W37: 0 | X37: 0 | Y37: 0 | Z37: 0 | AA37: 0 | AB37: 0 | AC37: 0 | AD37: 0 | AE37: 0 | AF37: 0 | AG37: 0
B39: 204030 | C39: 기타영업비용 | D39: Other Operating Expenses | J39: 0 | K39: 0 | L39: 0 | M39: 0 | N39: 0 | O39: 0 | P39: 0 | Q39: 0 | R39: 0 | S39: 0 | T39: 0 | U39: 0 | V39: 0 | W39: 0 | X39: 0 | Y39: 0 | Z39: 0 | AA39: 0 | AB39: 0 | AC39: 0 | AD39: 0 | AE39: 0 | AF39: 0 | AG39: 0
B40: 204040 | C40: 이자비용 | D40: Interest Expenses | J40: 0 | K40: 0 | L40: 0 | M40: 0 | N40: 0 | O40: 0 | P40: 0 | Q40: 0 | R40: 0 | S40: 0 | T40: 0 | U40: 0 | V40: 0 | W40: 0 | X40: 0 | Y40: 0 | Z40: 0 | AA40: 0 | AB40: 0 | AC40: 0 | AD40: 0 | AE40: 0 | AF40: 0 | AG40: 0
B41: 204050 | C41: 외환거래손실 | D41: Losses on Foreign Exchange | J41: 0 | K41: 0 | L41: 0 | M41: 0 | N41: 0 | O41: 0 | P41: 0 | Q41: 0 | R41: 0 | S41: 0 | T41: 0 | U41: 0 | V41: 0 | W41: 0 | X41: 0 | Y41: 0 | Z41: 0 | AA41: 0 | AB41: 0 | AC41: 0 | AD41: 0 | AE41: 0 | AF41: 0 | AG41: 0
B42: 204240 | C42: 투자자산평가손실 | D42: Losses on Investment Assets | J42: 0 | K42: 0 | L42: 0 | M42: 0 | N42: 0 | O42: 0 | P42: 0 | Q42: 0 | R42: 0 | S42: 0 | T42: 0 | U42: 0 | V42: 0 | W42: 0 | X42: 0 | Y42: 0 | Z42: 0 | AA42: 0 | AB42: 0 | AC42: 0 | AD42: 0 | AE42: 0 | AF42: 0 | AG42: 0
B43: 204031 | C43: 기타 기타비용 | D43: Others | J43: 0 | K43: 0 | L43: 0 | M43: 0 | N43: 0 | O43: 0 | P43: 0 | Q43: 0 | R43: 0 | S43: 0 | T43: 0 | U43: 0 | V43: 0 | W43: 0 | X43: 0 | Y43: 0 | Z43: 0 | AA43: 0 | AB43: 0 | AC43: 0 | AD43: 0 | AE43: 0 | AF43: 0 | AG43: 0
B45: 201370 | C45: 영업이익 | D45: Operating Income | J45: 171.481 | K45: 175.408 | L45: 153.706 | M45: 74.307 | N45: 173.512 | O45: 223.551 | P45: 243.869 | Q45: 144.498 | R45: 250.913 | S45: 147.303 | T45: 114.291 | U45: -1775.927 | V45: -2077.2566 | W45: -2077.2566 | X45: -2077.2566 | Y45: 4840.2523 | Z45: 5339.67 | AA45: 5339.67 | AB45: 5339.67 | AC45: -17525.746 | AD45: -19305.554 | AE45: -19305.554 | AF45: -19305.554 | AG45: 56274.724
... B72: 202890 | C72: 지분법관련손익 | D72: Gains(Losses) in Equity Method | J72: -1.529 | K72: 0.722 | L72: 0.863 | M72: -12.729 | N72: -1.094 | O72: -3.138 | P72: 0.666 | Q72: -1.714 | R72: -0.149 | S72: 0.919 | T72: -2.134 | U72: 6.939 | V72: 1.39375 | W72: 1.39375 | X72: 1.39375 | Y72: 1.39375 | Z72: 1.39375 | AA72: 1.39375 | AB72: 1.39375 | AC72: 1.39375 | AD72: 1.39375 | AE72: 1.39375 | AF72: 1.39375 | AG72: 1.39375
D73: Gains
D74: Losses
D75: Others
B76: 202990 | C76: 관계기업처분손익 | D76: Gains(Losses) in Associates | J76: 0 | K76: 0 | L76: 0 | M76: 0 | N76: 0 | O76: 0 | P76: 0 | Q76: 0 | R76: 0 | S76: 0 | T76: 0 | U76: 0 | V76: 0 | W76: 0 | X76: 0 | Y76: 0 | Z76: 0 | AA76: 0 | AB76: 0 | AC76: 0 | AD76: 0 | AE76: 0 | AF76: 0 | AG76: 0
B77: 203050 | C77: 종속기업관련손익 | D77: Gains(Losses) in Subsidiaries | J77: 0 | K77: 0 | L77: 0 | M77: 0 | N77: 0 | O77: 0 | P77: 0 | Q77: 0 | R77: 0 | S77: 0 | T77: 0 | U77: 0 | V77: 0 | W77: 0 | X77: 0 | Y77: 0 | Z77: 0 | AA77: 0 | AB77: 0 | AC77: 0 | AD77: 0 | AE77: 0 | AF77: 0 | AG77: 0
B78: 203110 | C78: 기타 | D78: Others | J78: 0 | K78: 0 | L78: 0 | M78: 0 | N78: 0 | O78: 0 | P78: 0 | Q78: 0 | R78: 0 | S78: 0 | T78: 0 | U78: 0 | V78: 0 | W78: 0 | X78: 0 | Y78: 0 | Z78: 0 | AA78: 0 | AB78: 0 | AC78: 0 | AD78: 0 | AE78: 0 | AF78: 0 | AG78: 0
B80: 203120 | C80: 세전이익 | D80: Pre-Tax Income | J80: 233.322 | K80: 321.728 | L80: 349.087 | M80: -150.322 | N80: 226.659 | O80: 240.13 | P80: 276.668 | Q80: 196.088 | R80: 302.796 | S80: 247.817 | T80: 85.012 | U80: -1621.342 | V80: -2088.8803 | W80: -2088.8803 | X80: -2088.8803 | Y80: 4828.6286 | Z80: 5326.7587 | AA80: 5326.7587 | AB80: 5326.7587 | AC80: -17538.657 | AD80: -19319.413 | AE80: -19319.413 | AF80: -19319.413 | AG80: 56260.864
B81: 203130 | C81: 법인세비용 | D81: Income Tax Expenses | J81: 50.214 | K81: 96.784 | L81: 114.289 | M81: 21.652 | N81: 76.107 | O81: 27.771 | P81: 95.343 | Q81: 86.043 | R81: 94.433 | S81: 101.7 | T81: 44.906 | U81: -460.535 | V81: -80.052876 | W81: -80.052876 | X81: -80.052876 | Y81: -80.052876 | Z81: -86.75371 | AA81: -86.75371 | AB81: -86.75371 | AC81: -86.75371 | AD81: -94.491404 | AE81: -94.491404 | AF81: -94.491404 | AG81: -94.491404
B82: 203165 | C82: 종속회사매수일전순손익 | D82: Others | J82: 0 | K82: 0 | L82: 0 | M82: 0 | N82: 0 | O82: 0 | P82: 0 | Q82: 0 | R82: 0 | S82: 0 | T82: 0 | U82: 0 | V82: 0 | W82: 0 | X82: 0 | Y82: 0 | Z82: 0 | AA82: 0 | AB82: 0 | AC82: 0 | AD82: 0 | AE82: 0 | AF82: 0 | AG82: 0
B83: 205560 | C83: 처분된종속회사순손익 | D83: Net Income(Net Loss) from Disposed Subsidies | J83: 0 | K83: 0 | L83: 0 | M83: 0 | N83: 0 | O83: 0 | P83: 0 | Q83: 0 | R83: 0 | S83: 0 | T83: 0 | U83: 0 | V83: 0 | W83: 0 | X83: 0 | Y83: 0 | Z83: 0 | AA83: 0 | AB83: 0 | AC83: 0 | AD83: 0 | AE83: 0 | AF83: 0 | AG83: 0
B84: 203140 | C84: 계속사업이익 | D84: Income from Continuing Operations | J84: 183.108 | K84: 224.944 | L84: 234.798 | M84: -171.974 | N84: 150.552 | O84: 212.359 | P84: 181.325 | Q84: 110.045 | R84: 208.363 | S84: 146.117 | T84: 40.106 | U84: -1160.807 | V84: -2008.8274 | W84: -2008.8274 | X84: -2008.8274 | Y84: 4908.6815 | Z84: 5413.5124 | AA84: 5413.5124 | AB84: 5413.5124 | AC84: -17451.904 | AD84: -19224.922 | AE84: -19224.922 | AF84: -19224.922 | AG84: 56355.356
...

Sheet ForecastQ
C2: ForecastQ | D2: ForecastQ | AS2: Income Statement | DB2: Annual
AS3: Balance Sheet
AO4: History | AS4: Cash Flow Statements
B5: Period_CY_ | C5: (*) 우측(DF열)에서 연간금액 조회 가능 | J5: 2008.03 | K5: 2008.06 | L5: 2008.09 | M5: 2008.12 | N5: 2009.03 | O5: 2009.06 | P5: 2009.09 | Q5: 2009.12 | R5: 2010.03 | S5: 2010.06 | T5: 2010.09 | U5: 2010.12 | V5: 2011.03 | W5: 2011.06 | X5: 2011.09 | Y5: 2011.12 | Z5: 2012.03 | AA5: 2012.06 | AB5: 2012.09 | AC5: 2012.12 | AD5: 2013.03 | AE5: 2013.06 | AF5: 2013.09 | AG5: 2013.12 | AH5: 2014.03 | AI5: 2014.06 | AJ5: 2014.09 | AK5: 2014.12 | AL5: 2015.03 | AM5: 2015.06 | AN5: 2015.09 | AO5: 2015.12 | AP5: 2016.03 | AQ5: 2016.06 | AR5: 2016.09 | AS5: 2016.12 | AT5: 2017.03 | AU5: 2017.06 | AV5: 2017.09 | AW5: 2017.12 | AX5: 2018.03 | AY5: 2018.06 | AZ5: 2018.09 | BA5: 2018.12 | BB5: 2019.03 | BC5: 2019.06 | BD5: 2019.09 | BE5: 2019.12 | BF5: 2020.03 | BG5: 2020.06 | BH5: 2020.09 | BI5: 2020.12 | BJ5: 2021.03 | BK5: 2021.06 | BL5: 2021.09 | BM5: 2021.12 | BN5: 2022.03 | BO5: 2022.06 | BP5: 2022.09 | BQ5: 2022.12 | BR5: 2023.03 | BS5: 2023.06 | BT5: 2023.09 | BU5: 2023.12 | BV5: 2024.03 | BW5: 2024.06 | BX5: 2024.09 | BY5: 2024.12 | BZ5: 2025.03 | CA5: 2025.06 | CB5: 2025.09 | CC5: 2025.12 | CD5: 2026.03 | CE5: 2026.06 | CF5: 2026.09 | CG5: 2026.12 | CH5: 2027.03 | CI5: 2027.06 | CJ5: 2027.09 | CK5: 2027.12 | CL5: 2028.03 | CM5: 2028.06 | CN5: 2028.09 | CO5: 2028.12 | CP5: 2029.03 | CQ5: 2029.06 | CR5: 2029.09 | CS5: 2029.12 | CT5: 2030.03 | CU5: 2030.06 | CV5: 2030.09 | CW5: 2030.12 | DA5: Period_CY_ | DC5: 2008.12 | DD5: 2009.12 | DE5: 2010.12 | DF5: 2011.12 | DG5: 2012.12 | DH5: 2013.12 | DI5: 2014.12 | DJ5: 2015.12 | DK5: 2016.12 | DL5: 2017.12 | DM5: 2018.12 | DN5: 2019.12
B6: Period_FY_ | J6: 2008_1A | K6: 2008_2A | L6: 2008_3A | M6: 2008_4A | N6: 2009_1A | O6: 2009_2A | P6: 2009_3A | Q6: 2009_4A | R6: 2010_1A | S6: 2010_2A | T6: 2010_3A | U6: 2010_4A | V6: 2011_1A | W6: 2011_2A | X6: 2011_3A | Y6: 2011_4A | Z6: 2012_1A | AA6: 2012_2A | AB6: 2012_3A | AC6: 2012_4A | AD6: 2013_1A | AE6: 2013_2A | AF6: 2013_3A | AG6: 2013_4A | AH6: 2014_1A | AI6: 2014_2A | AJ6: 2014_3A | AK6: 2014_4A | AL6: 2015_1A | AM6: 2015_2A | AN6: 2015_3A | AO6: 2015_4A | AP6: 2016_1A | AQ6: 2016_2A | AR6: 2016_3A | AS6: 2016_4A | AT6: 2017_1A | AU6: 2017_2A | AV6: 2017_3A | AW6: 2017_4A | AX6: 2018_1A | AY6: 2018_2A | AZ6: 2018_3A | BA6: 2018_4A | BB6: 2019_1A | BC6: 2019_2A | BD6: 2019_3A | BE6: 2019_4A | BF6: 2020_1A | BG6: 2020_2A | BH6: 2020_3A | BI6: 2020_4A | BJ6: 2021_1A | BK6: 2021_2A | BL6: 2021_3A | BM6: 2021_4A | BN6: 2022_1A | BO6: 2022_2A | BP6: 2022_3A | BQ6: 2022_4A | BR6: 2023_1A | BS6: 2023_2A | BT6: 2023_3A | BU6: 2023_4A | BV6: 2024_1A | BW6: 2024_2A | BX6: 2024_3A | BY6: 2024_4A | BZ6: 2025_1F | CA6: 2025_2F | CB6: 2025_3F | CC6: 2025_4F | CD6: 2026_1F | CE6: 2026_2F | CF6: 2026_3F | CG6: 2026_4F | CH6: 2027_1F | CI6: 2027_2F | CJ6: 2027_3F | CK6: 2027_4F | CL6: 2028_1F | CM6: 2028_2F | CN6: 2028_3F | CO6: 2028_4F | CP6: 2029_1F | CQ6: 2029_2F | CR6: 2029_3F | CS6: 2029_4F | CT6: 2030_1F | CU6: 2030_2F | CV6: 2030_3F | CW6: 2030_4F | DA6: Period_FY_ | DC6: 2008A | DD6: 2009A | DE6: 2010A | DF6: 2011A | DG6: 2012A | DH6: 2013A | DI6: 2014A | DJ6: 2015A | DK6: 2016A | DL6: 2017A | DM6: 2018A | DN6: 2019A
C8: Balance_BS : Asset - (Liability + Equity) | D8: BS: A-(L+E) | BZ8: -5477.7124 | CA8: -5825.0527 | CB8: -6172.3931 | CC8: -6519.7335 | CD8: -7244.0848 | CE8: -7968.4362 | CF8: -8692.7875 | CG8: -9417.1389 | CH8: -10791.209 | CI8: -12165.278 | CJ8: -13539.348 | CK8: -14913.418 | CL8: -17362.768 | CM8: -19812.118 | CN8: -22261.468 | CO8: -24710.818 | CP8: -28904.055 | CQ8: -33097.293 | CR8: -37290.53 | CS8: -41483.768 | CT8: -48473.703 | CU8: -55463.638 | CV8: -62453.573 | CW8: -69443.508 | CX8: FALSE
C9: Balance_CF : Cash(BS) - Cash(CF) | D9: CF: Cash(BS) - Cash(CF) | BZ9: -4114.8576 | CA9: -3099.3432 | CB9: -2083.8289 | CC9: -6753.8315 | CD9: -13592.418 | CE9: -20431.004 | CF9: -27269.59 | CG9: -9885.3349 | CH9: 7203.2329 | CI9: 24291.801 | CJ9: 41380.369 | CK9: -15615.712 | CL9: -80992.095 | CM9: -146368.48 | CN9: -211744.86 | CO9: -25647.21 | CP9: 176093.48 | CQ9: 377834.16 | CR9: 579574.85 | CS9: -42654.258 | CT9: -732599.1 | CU9: -1422543.9 | CV9: -2112488.8 | CW9: -70848.096 | CX9: FALSE
A13: Income Statement | CZ13: Income Statement
B15: 200000 | C15: 매출액 | D15: Sales | J15: 0 | K15: 0 | L15: 0 | M15: 0 | N15: 0 | O15: 0 | P15: 0 | Q15: 0 | R15: 0 | S15: 0 | T15: 0 | U15: 0 | V15: 2285.5006 | W15: 2870.005 | X15: 2961.7368 | Y15: 3802.9246 | Z15: 2705.571 | AA15: 3181.345 | AB15: 3319.281 | AC15: 4118.624 | AD15: 2861.221 | AE15: 3470.697 | AF15: 3534.919 | AG15: 3985.205 | AH15: 3290.554 | AI15: 4702.888 | AJ15: 4259.166 | AK15: 5023.872 | AL15: 3943.209 | AM15: 4815.544 | AN15: 4711.383 | AO15: 5763.044 | AP15: 4287.904 | AQ15: 4686.557 | AR15: 4464.114 | AS15: 5386.44 | AT15: 4129.693 | AU15: 4217.811 | AV15: 4243.113 | AW15: 4296.473 | AX15: 3538.167 | AY15: 4240.094 | AZ15: 4486.329 | BA15: 4466.304 | BB15: 3877.659 | BC15: 4681.888 | BD15: 4087.761 | BE15: 4631.484 | BF15: 4058.864 | BG15: 4544.15 | BH15: 4042.483 | BI15: 4325.362 | BJ15: 4149.57 | BK15: 4383.532 | BL15: 4351.948 | BM15: 5180.484 | BN15: 4145.303 | BO15: 5579.448 | BP15: 5430.844 | BQ15: 6083.487 | BR15: 6031.081 | BS15: 7163.359 | BT15: 7858.53 | BU15: 8598.387 | BV15: 8545.258 | BW15: 8621.236 | BX15: 8256.906 | BY15: 7246.868 | BZ15: 8999.1363 | CA15: 8999.1363 | CB15: 8999.1363 | CC15: 8999.1363 | CD15: 9915.3706 | CE15: 9915.3706 | CF15: 9915.3706 | CG15: 9915.3706 | CH15: 10924.89 | CI15: 10924.89 | CJ15: 10924.89 | CK15: 10924.89 | CL15: 12037.192 | CM15: 12037.192 | CN15: 12037.192 | CO15: 12037.192 | CP15: 13262.742 | CQ15: 13262.742 | CR15: 13262.742 | CS15: 13262.742 | CT15: 14613.069 | CU15: 14613.069 | CV15: 14613.069 | CW15: 14613.069 | DA15: 200000 | DB15: 매출액 | DC15: 8036.4935 | DD15: 10390.595 | DE15: 11217.013 | DF15: 11920.167 | DG15: 13324.821 | DH15: 13852.042 | DI15: 17276.48 | DJ15: 19233.18 | DK15: 18825.015 | DL15: 16887.09 | DM15: 16730.894 | DN15: 17278.792
C16: (분기배분, manual) | D16: (% growth) | J16: 0 | K16: 0 | L16: 0 | M16: 0 | N16: 0 | O16: 0 | P16: 0 | Q16: 0 | R16: 0 | S16: 0 | T16: 0 | U16: 0 | V16: 0.19173394 | W16: 0.24076886 | X16: 0.24846437 | Y16: 0.31903283 | Z16: 0.20304746 | AA16: 0.2387533 | AB16: 0.24910511 | AC16: 0.30909413 | AD16: 0.2065559 | AE16: 0.2505549 | AF16: 0.25519118 | AG16: 0.28769802 | AH16: 0.19046438 | AI16: 0.27221332 | AJ16: 0.24652973 | AK16: 0.29079257 | AL16: 0.20502117 | AM16: 0.2503769 | AN16: 0.24496121 | AO16: 0.29964073 | AP16: 0.22777692 | AQ16: 0.24895369 | AR16: 0.23713734 | AS16: 0.28613204 | AT16: 0.24454734 | AU16: 0.24976541 | AV16: 0.25126372 | AW16: 0.25442353 | AX16: 0.21147507 | AY16: 0.25342902 | AZ16: 0.2681464 | BA16: 0.26694951 | BB16: 0.22441725 | BC16: 0.27096153 | BD16: 0.23657678 | BE16: 0.26804443 | BF16: 0.23916668 | BG16: 0.26776193 | BH16: 0.23820144 | BI16: 0.25486995 | BJ16: 0.2296954 | BK16: 0.24264613 | BL16: 0.24089783 | BM16: 0.28676063 | BN16: 0.19517336 | BO16: 0.26269723 | BP16: 0.25570051 | BQ16: 0.2864289 | BR16: 0.20339983 | BS16: 0.24158621 | BT16: 0.26503104 | BU16: 0.28998292 | BV16: 0.26156069 | BW16: 0.2638863 | BX16: 0.25273457 | BY16: 0.22181844 | BZ16: 0.25 | CA16: 0.25 | CB16: 0.25 | CC16: 0.25 | CD16: 0.25 | CE16: 0.25 | CF16: 0.25 | CG16: 0.25 | CH16: 0.25 | CI16: 0.25 | CJ16: 0.25 | CK16: 0.25 | CL16: 0.25 | CM16: 0.25 | CN16: 0.25 | CO16: 0.25 | CP16: 0.25 | CQ16: 0.25 | CR16: 0.25 | CS16: 0.25 | CT16: 0.25 | CU16: 0.25 | CV16: 0.25 | CW16: 0.25
B18: 200360 | C18: 매출원가 | D18: Cost of Sales | J18: 0 | K18: 0 | L18: 0 | M18: 0 | N18: 0 | O18: 0 | P18: 0 | Q18: 0 | R18: 0 | S18: 0 | T18: 0 | U18: 0 | V18: 2036.8264 | W18: 2566.8424 | X18: 2604.2633 | Y18: 3543.9239 | Z18: 2461.555 | AA18: 2906.66 | AB18: 2959.784 | AC18: 3747.95 | AD18: 2590.228 | AE18: 3162.457 | AF18: 3225.819 | AG18: 3753.861 | AH18: 2997.44 | AI18: 4234.801 | AJ18: 3897.897 | AK18: 4734.768 | AL18: 3603.914 | AM18: 4418.6 | AN18: 4308.803 | AO18: 5176.821 | AP18: 3925.333 | AQ18: 4180.289 | AR18: 4012.663 | AS18: 4776.99 | AT18: 3682.38 | AU18: 3746.099 | AV18: 3806.151 | AW18: 3873.496 | AX18: 3120.923 | AY18: 3801.835 | AZ18: 4044.589 | BA18: 4102.4 | BB18: 3487.987 | BC18: 4217.189 | BD18: 3671.56 | BE18: 4176.151 | BF18: 3623.956 | BG18: 4229.87 | BH18: 3694.079 | BI18: 4026.091 | BJ18: 3749.802 | BK18: 3965.536 | BL18: 3930.467 | BM18: 4622.493 | BN18: 3774.063 | BO18: 5137.759 | BP18: 5097.562 | BQ18: 5716.95 | BR18: 5651.16 | BS18: 6765.776 | BT18: 7342.408 | BU18: 8189.205 | BV18: 8011.925 | BW18: 8279.049 | BX18: 7908.598 | BY18: 8687.629 | BZ18: 10788.268 | CA18: 10788.268 | CB18: 10788.268 | CC18: 3870.7595 | CD18: 4264.8554 | CE18: 4264.8554 | CF18: 4264.8554 | CG18: 27130.271 | CH18: 29892.502 | CI18: 29892.502 | CJ18: 29892.502 | CK18: -45687.776 | CL18: -50339.413 | CM18: -50339.413 | CN18: -50339.413 | CO18: 199486.72 | CP18: 219797.18 | CQ18: 219797.18 | CR18: 219797.18 | CS18: -605988.3 | CT18: -667686.14 | CU18: -667686.14 | CV18: -667686.14 | CW18: 2061898.8 | DA18: 200360 | DB18: 매출원가 | DC18: 7148.7166 | DD18: 9441.7516 | DE18: 9908.9062 | DF18: 10751.856 | DG18: 12075.949 | DH18: 12732.365 | DI18: 15864.906 | DJ18: 17508.138 | DK18: 16895.275 | DL18: 15108.126 | DM18: 15069.747 | DN18: 15552.887
C19: (% of sales, manual) | D19: (% of sales) | J19: 0 | K19: 0 | L19: 0 | M19: 0 | N19: 0 | O19: 0 | P19: 0 | Q19: 0 | R19: 0 | S19: 0 | T19: 0 | U19: 0 | V19: 0.89119486 | W19: 0.8943686 | X19: 0.87930276 | Y19: 0.93189434 | Z19: 0.9098098 | AA19: 0.91365759 | AB19: 0.89169432 | AC19: 0.91000052 | AD19: 0.90528764 | AE19: 0.91118787 | AF19: 0.91255811 | AG19: 0.94194928 | AH19: 0.9109226 | AI19: 0.90046818 | AJ19: 0.91517846 | AK19: 0.94245395 | AL19: 0.9139546 | AM19: 0.91757027 | AN19: 0.91455163 | AO19: 0.89827893 | AP19: 0.9154433 | AQ19: 0.89197443 | AR19: 0.89887109 | AS19: 0.88685477 | AT19: 0.89168372 | AU19: 0.88816189 | AV19: 0.89701853 | AW19: 0.90155251 | AX19: 0.8820734 | AY19: 0.89663932 | AZ19: 0.90153642 | BA19: 0.91852234 | BB19: 0.89950844 | BC19: 0.90074538 | BD19: 0.89818363 | BE19: 0.90168745 | BF19: 0.89284982 | BG19: 0.93083855 | BH19: 0.91381436 | BI19: 0.93081018 | BJ19: 0.90366038 | BK19: 0.90464402 | BL19: 0.90315119 | BM19: 0.89228979 | BN19: 0.91044322 | BO19: 0.92083643 | BP19: 0.93863164 | BQ19: 0.93974886 | BR19: 0.93700615 | BS19: 0.94449769 | BT19: 0.93432334 | BU19: 0.95241177 | BV19: 0.93758726 | BW19: 0.96030882 | BX19: 0.95781616 | BY19: 1.1988115 | BZ19: 1.1988115 | CA19: 1.1988115 | CB19: 1.1988115 | CC19: 0.43012567 | CD19: 0.43012567 | CE19: 0.43012567 | CF19: 0.43012567 | CG19: 2.7361833 | CH19: 2.7361833 | CI19: 2.7361833 | CJ19: 2.7361833 | CK19: -4.1819896 | CL19: -4.1819896 | CM19: -4.1819896 | CN19: -4.1819896 | CO19: 16.572529 | CP19: 16.572529 | CQ19: 16.572529 | CR19: 16.572529 | CS19: -45.691027 | CT19: -45.691027 | CU19: -45.691027 | CV19: -45.691027 | CW19: 141.09964
B21: 200810 | C21: 매출총이익 | D21: Gross Profit | J21: 0 | K21: 0 | L21: 0 | M21: 0 | N21: 0 | O21: 0 | P21: 0 | Q21: 0 | R21: 0 | S21: 0 | T21: 0 | U21: 0 | V21: 248.67422 | W21: 303.16264 | X21: 357.47346 | Y21: 259.00068 | Z21: 244.016 | AA21: 274.685 | AB21: 359.497 | AC21: 370.674 | AD21: 270.993 | AE21: 308.24 | AF21: 309.1 | AG21: 231.344 | AH21: 293.114 | AI21: 468.087 | AJ21: 361.269 | AK21: 289.104 | AL21: 339.295 | AM21: 396.944 | AN21: 402.58 | AO21: 586.223 | AP21: 362.571 | AQ21: 506.268 | AR21: 451.451 | AS21: 609.45 | AT21: 447.313 | AU21: 471.712 | AV21: 436.962 | AW21: 422.977 | AX21: 417.244 | AY21: 438.259 | AZ21: 441.74 | BA21: 363.904 | BB21: 389.672 | BC21: 464.699 | BD21: 416.201 | BE21: 455.333 | BF21: 434.908 | BG21: 314.28 | BH21: 348.404 | BI21: 299.271 | BJ21: 399.768 | BK21: 417.996 | BL21: 421.481 | BM21: 557.991 | BN21: 371.24 | BO21: 441.689 | BP21: 333.282 | BQ21: 366.537 | BR21: 379.921 | BS21: 397.583 | BT21: 516.122 | BU21: 409.182 | BV21: 533.333 | BW21: 342.187 | BX21: 348.308 | BY21: -1440.761 | BZ21: -1789.1322 | CA21: -1789.1322 | CB21: -1789.1322 | CC21: 5128.3768 | CD21: 5650.5152 | CE21: 5650.5152 | CF21: 5650.5152 | CG21: -17214.901 | CH21: -18967.612 | CI21: -18967.612 | CJ21: -18967.612 | CK21: 56612.666 | CL21: 62376.605 | CM21: 62376.605 | CN21: 62376.605 | CO21: -187449.53 | CP21: -206534.43 | CQ21: -206534.43 | CR21: -206534.43 | CS21: 619251.04 | CT21: 682299.21 | CU21: 682299.21 | CV21: 682299.21 | CW21: -2047285.8 | DA21: 200810 | DB21: 매출총이익 | DC21: 887.77696 | DD21: 948.84324 | DE21: 1308.1073 | DF21: 1168.311 | DG21: 1248.872 | DH21: 1119.677 | DI21: 1411.574 | DJ21: 1725.042 | DK21: 1929.74 | DL21: 1778.964 | DM21: 1661.147 | DN21: 1725.905
C22: (% of sales) | D22: (% of sales) | J22: 0 | K22: 0 | L22: 0 | M22: 0 | N22: 0 | O22: 0 | P22: 0 | Q22: 0 | R22: 0 | S22: 0 | T22: 0 | U22: 0 | V22: 0.10880514 | W22: 0.1056314 | X22: 0.12069724 | Y22: 0.068105657 | Z22: 0.090190204 | AA22: 0.086342412 | AB22: 0.10830568 | AC22: 0.089999476 | AD22: 0.094712362 | AE22: 0.088812132 | AF22: 0.08744189 | AG22: 0.058050715 | AH22: 0.089077402 | AI22: 0.09953182 | AJ22: 0.084821535 | AK22: 0.057546052 | AL22: 0.086045401 | AM22: 0.082429732 | AN22: 0.08544837 | AO22: 0.10172107 | AP22: 0.084556697 | AQ22: 0.10802557 | AR22: 0.10112891 | AS22: 0.11314523 | AT22: 0.10831628 | AU22: 0.11183811 | AV22: 0.10298147 | AW22: 0.098447494 | AX22: 0.1179266 | AY22: 0.10336068 | AZ22: 0.098463577 | BA22: 0.08147766 | BB22: 0.10049156 | BC22: 0.099254617 | BD22: 0.10181637 | BE22: 0.098312549 | BF22: 0.10715018 | BG22: 0.069161449 | BH22: 0.086185644 | BI22: 0.069189816 | BJ22: 0.096339621 | BK22: 0.095355982 | BL22: 0.096848813 | BM22: 0.10771021 | BN22: 0.089556783 | BO22: 0.079163566 | BP22: 0.061368362 | BQ22: 0.060251136 | BR22: 0.062993848 | BS22: 0.055502314 | BT22: 0.06567666 | BU22: 0.047588228 | BV22: 0.062412744 | BW22: 0.039691177 | BX22: 0.04218384 | BY22: -0.19881154 | BZ22: -0.19881154 | CA22: -0.19881154 | CB22: -0.19881154 | CC22: 0.56987433 | CD22: 0.56987433 | CE22: 0.56987433 | CF22: 0.56987433 | CG22: -1.7361833 | CH22: -1.7361833 | CI22: -1.7361833 | CJ22: -1.7361833 | CK22: 5.1819896 | CL22: 5.1819896 | CM22: 5.1819896 | CN22: 5.1819896 | CO22: -15.572529 | CP22: -15.572529 | CQ22: -15.572529 | CR22: -15.572529 | CS22: 46.691027 | CT22: 46.691027 | CU22: 46.691027 | CV22: 46.691027 | CW22: -140.09964
B25: 200820 | C25: 판매비와 관리비 | D25: SG&A | J25: 0 | K25: 0 | L25: 0 | M25: 0 | N25: 0 | O25: 0 | P25: 0 | Q25: 0 | R25: 0 | S25: 0 | T25: 0 | U25: 0 | V25: 97.800588 | W25: 112.58617 | X25: 102.7165 | Y25: 119.61174 | Z25: 97.446 | AA25: 117.216 | AB25: 139.77 | AC25: 134.032 | AD25: 92.356 | AE25: 107.588 | AF25: 103.047 | AG25: 112.589 | AH25: 105.46 | AI25: 188.519 | AJ25: 130.57 | AK25: 157.83 | AL25: 138.641 | AM25: 142.636 | AN25: 138.187 | AO25: 216.25 | AP25: 155.395 | AQ25: 237.869 | AR25: 176.331 | AS25: 201.186 | AT25: 218.681 | AU25: 189.914 | AV25: 155.911 | AW25: 228.353 | AX25: 198.774 | AY25: 217.372 | AZ25: 203.821 | BA25: 201.191 | BB25: 184.469 | BC25: 219.609 | BD25: 177.039 | BE25: 285.121 | BF25: 269.561 | BG25: 160.422 | BH25: 208.558 | BI25: 209.35 | BJ25: 198.869 | BK25: 277.028 | BL25: 201.117 | BM25: 366.718 | BN25: 199.759 | BO25: 266.281 | BP25: 179.576 | BQ25: 292.23 | BR25: 206.409 | BS25: 174.032 | BT25: 272.253 | BU25: 264.684 | BV25: 282.42 | BW25: 194.884 | BX25: 234.017 | BY25: 335.166 | BZ25: 288.12446 | CA25: 288.12446 | CB25: 288.12446 | CC25: 288.12446 | CD25: 310.84517 | CE25: 310.84517 | CF25: 310.84517 | CG25: 310.84517 | CH25: 337.94268 | CI25: 337.94268 | CJ25: 337.94268 | CK25: 337.94268 | CL25: 369.19855 | CM25: 369.19855 | CN25: 369.19855 | CO25: 369.19855 | CP25: 404.58782 | CQ25: 404.58782 | CR25: 404.58782 | CS25: 404.58782 | CT25: 444.22842 | CU25: 444.22842 | CV25: 444.22842 | CW25: 444.22842 | DA25: 200820 | DB25: 판매비와 관리비 | DC25: 320.87371 | DD25: 367.80215 | DE25: 552.8057 | DF25: 432.715 | DG25: 488.464 | DH25: 415.58 | DI25: 582.379 | DJ25: 635.714 | DK25: 770.781 | DL25: 792.859 | DM25: 821.158 | DN25: 866.238
